<mujocoinclude>
    <body childclass="drawer_base">
        <body name="drawercase_link" pos="0 0 0.084">
            <joint type="slide" range="-0.12 0.12" axis="1 0 0" name="drawer_slidex" pos="0 0 0" damping="10000000"/>
            <joint type="slide" range="-0.1 0.1" axis="0 1 0" name="drawer_slidey" pos="0 0 0" damping="10000000"/>
            <geom rgba="1 0.5 0 0.6" mesh="drawercase" conaffinity="1" condim="4" contype="1" gap="0.001" margin="0.001"/>

            <geom class="drawer_col" pos="-0.11 0 0" size="0.008 0.1 0.084" type="box" mass=".05" conaffinity="1" condim="4" contype="1"/>
            <geom class="drawer_col" pos="0.11 0 0" size="0.008 0.1 0.084" type="box" mass=".05" conaffinity="1" condim="4" contype="1"/>
            <geom class="drawer_col" pos="0 0.092 -0.008" size="0.102 0.008 0.076" type="box" mass=".05" conaffinity="1" condim="4" contype="1"/>
            <geom class="drawer_col" pos="0 -0.008 -0.07" size="0.102 0.092 0.014" type="box" mass=".05" conaffinity="1" condim="4" contype="1"/>
            <geom class="drawer_col" pos="0 0 0.076" size="0.102 0.1 0.008" type="box" mass=".05" conaffinity="1" condim="4" contype="1"/>

            <body name="drawer_link" pos="0 -0.01 0.006">
                <joint type="slide" range="-0.16 0.04" axis="0 1 0" name="goal_slidey" pos="0 0 0" damping="10000"/>
                <geom material="drawer_beige" mesh="drawer" conaffinity="1" condim="3" contype="1" friction="1 1 1" gap="0.001"/>
                <!--<geom material="drawer_white" euler="1.57 0 0" pos="0 -0.14 0.04" size="0.015  0.01" type="cylinder" />-->

                <geom material="drawer_white" euler="1.57 0 0" pos="0 -0.114 0.04" size="0.01 0.01 0.05" type="box" name="objGeom"
                      conaffinity="1" condim="3" contype="1" friction="1 1 1"
                />
                <!--<geom material="drawer_white" mesh="drawerhandle" pos="0 -0.114 0" name="objGeom"/>-->
                <site name="objGeom" pos="0.0 -0.152 0.04" size="0.012" rgba="1 1 0 1"/>
                <geom class="drawer_col" pos="0 -0.082 0.008" size="0.1 0.008 0.052" type="box" mass=".04"/>
                <geom class="drawer_col" pos="0 0.082 0.008" size="0.1 0.008 0.052" type="box" mass=".04"/>
                <geom class="drawer_col" pos="-0.092 0 0.008" size="0.008 0.074 0.052" type="box" mass=".04"/>
                <geom class="drawer_col" pos="0.092 0 0.008" size="0.008 0.074 0.052" type="box" mass=".04"/>
                <geom class="drawer_col" pos="0 0 -0.052" size="0.1 0.09 0.008" type="box" mass=".04"/>
                <geom class="drawer_col" euler="1.571 0 0" pos="-0.05 -0.12 0.0" size="0.009 0.03" type="capsule" mass=".06"/>
                <geom class="drawer_col" euler="0 1.57 0" pos="0 -0.15 0" size="0.009 0.05" type="capsule" mass=".06"/>
                <geom class="drawer_col" euler="1.57 0 0" pos="0.05 -0.12 0" size="0.009 0.03" type="capsule" mass=".06"/>

            </body>
        </body>
    </body>
</mujocoinclude>
